Initializing database...
Traceback (most recent call last):
  File "/Users/vrushank/Desktop/WORKSPACE/Agnoster/venv/lib/python3.12/site-packages/sqlalchemy/engine/base.py", line 145, in __init__
    self._dbapi_connection = engine.raw_connection()
                             ^^^^^^^^^^^^^^^^^^^^^^^
  File "/Users/vrushank/Desktop/WORKSPACE/Agnoster/venv/lib/python3.12/site-packages/sqlalchemy/engine/base.py", line 3282, in raw_connection
    return self.pool.connect()
           ^^^^^^^^^^^^^^^^^^^
  File "/Users/vrushank/Desktop/WORKSPACE/Agnoster/venv/lib/python3.12/site-packages/sqlalchemy/pool/base.py", line 449, in connect
    return _ConnectionFairy._checkout(self)
           ^^^^^^^^^^^^^^^^^^^^^^^^^^^^^^^^
  File "/Users/vrushank/Desktop/WORKSPACE/Agnoster/venv/lib/python3.12/site-packages/sqlalchemy/pool/base.py", line 1263, in _checkout
    fairy = _ConnectionRecord.checkout(pool)
            ^^^^^^^^^^^^^^^^^^^^^^^^^^^^^^^^
  File "/Users/vrushank/Desktop/WORKSPACE/Agnoster/venv/lib/python3.12/site-packages/sqlalchemy/pool/base.py", line 712, in checkout
    rec = pool._do_get()
          ^^^^^^^^^^^^^^
  File "/Users/vrushank/Desktop/WORKSPACE/Agnoster/venv/lib/python3.12/site-packages/sqlalchemy/pool/impl.py", line 168, in _do_get
    with util.safe_reraise():
  File "/Users/vrushank/Desktop/WORKSPACE/Agnoster/venv/lib/python3.12/site-packages/sqlalchemy/util/langhelpers.py", line 146, in __exit__
    raise exc_value.with_traceback(exc_tb)
  File "/Users/vrushank/Desktop/WORKSPACE/Agnoster/venv/lib/python3.12/site-packages/sqlalchemy/pool/impl.py", line 166, in _do_get
    return self._create_connection()
           ^^^^^^^^^^^^^^^^^^^^^^^^^
  File "/Users/vrushank/Desktop/WORKSPACE/Agnoster/venv/lib/python3.12/site-packages/sqlalchemy/pool/base.py", line 390, in _create_connection
    return _ConnectionRecord(self)
           ^^^^^^^^^^^^^^^^^^^^^^^
  File "/Users/vrushank/Desktop/WORKSPACE/Agnoster/venv/lib/python3.12/site-packages/sqlalchemy/pool/base.py", line 674, in __init__
    self.__connect()
  File "/Users/vrushank/Desktop/WORKSPACE/Agnoster/venv/lib/python3.12/site-packages/sqlalchemy/pool/base.py", line 900, in __connect
    with util.safe_reraise():
  File "/Users/vrushank/Desktop/WORKSPACE/Agnoster/venv/lib/python3.12/site-packages/sqlalchemy/util/langhelpers.py", line 146, in __exit__
    raise exc_value.with_traceback(exc_tb)
  File "/Users/vrushank/Desktop/WORKSPACE/Agnoster/venv/lib/python3.12/site-packages/sqlalchemy/pool/base.py", line 896, in __connect
    self.dbapi_connection = connection = pool._invoke_creator(self)
                                         ^^^^^^^^^^^^^^^^^^^^^^^^^^
  File "/Users/vrushank/Desktop/WORKSPACE/Agnoster/venv/lib/python3.12/site-packages/sqlalchemy/engine/create.py", line 643, in connect
    return dialect.connect(*cargs, **cparams)
           ^^^^^^^^^^^^^^^^^^^^^^^^^^^^^^^^^^
  File "/Users/vrushank/Desktop/WORKSPACE/Agnoster/venv/lib/python3.12/site-packages/sqlalchemy/engine/default.py", line 616, in connect
    return self.loaded_dbapi.connect(*cargs, **cparams)
           ^^^^^^^^^^^^^^^^^^^^^^^^^^^^^^^^^^^^^^^^^^^^
sqlite3.OperationalError: unable to open database file

The above exception was the direct cause of the following exception:

Traceback (most recent call last):
  File "<string>", line 1, in <module>
  File "/Users/vrushank/Desktop/WORKSPACE/Agnoster/app.py", line 56, in <module>
    db.create_all()
  File "/Users/vrushank/Desktop/WORKSPACE/Agnoster/venv/lib/python3.12/site-packages/flask_sqlalchemy/extension.py", line 900, in create_all
    self._call_for_binds(bind_key, "create_all")
  File "/Users/vrushank/Desktop/WORKSPACE/Agnoster/venv/lib/python3.12/site-packages/flask_sqlalchemy/extension.py", line 881, in _call_for_binds
    getattr(metadata, op_name)(bind=engine)
  File "/Users/vrushank/Desktop/WORKSPACE/Agnoster/venv/lib/python3.12/site-packages/sqlalchemy/sql/schema.py", line 5825, in create_all
    bind._run_ddl_visitor(
  File "/Users/vrushank/Desktop/WORKSPACE/Agnoster/venv/lib/python3.12/site-packages/sqlalchemy/engine/base.py", line 3232, in _run_ddl_visitor
    with self.begin() as conn:
  File "/Library/Frameworks/Python.framework/Versions/3.12/lib/python3.12/contextlib.py", line 137, in __enter__
    return next(self.gen)
           ^^^^^^^^^^^^^^
  File "/Users/vrushank/Desktop/WORKSPACE/Agnoster/venv/lib/python3.12/site-packages/sqlalchemy/engine/base.py", line 3222, in begin
    with self.connect() as conn:
         ^^^^^^^^^^^^^^
  File "/Users/vrushank/Desktop/WORKSPACE/Agnoster/venv/lib/python3.12/site-packages/sqlalchemy/engine/base.py", line 3258, in connect
    return self._connection_cls(self)
           ^^^^^^^^^^^^^^^^^^^^^^^^^^
  File "/Users/vrushank/Desktop/WORKSPACE/Agnoster/venv/lib/python3.12/site-packages/sqlalchemy/engine/base.py", line 147, in __init__
    Connection._handle_dbapi_exception_noconnection(
  File "/Users/vrushank/Desktop/WORKSPACE/Agnoster/venv/lib/python3.12/site-packages/sqlalchemy/engine/base.py", line 2422, in _handle_dbapi_exception_noconnection
    raise sqlalchemy_exception.with_traceback(exc_info[2]) from e
  File "/Users/vrushank/Desktop/WORKSPACE/Agnoster/venv/lib/python3.12/site-packages/sqlalchemy/engine/base.py", line 145, in __init__
    self._dbapi_connection = engine.raw_connection()
                             ^^^^^^^^^^^^^^^^^^^^^^^
  File "/Users/vrushank/Desktop/WORKSPACE/Agnoster/venv/lib/python3.12/site-packages/sqlalchemy/engine/base.py", line 3282, in raw_connection
    return self.pool.connect()
           ^^^^^^^^^^^^^^^^^^^
  File "/Users/vrushank/Desktop/WORKSPACE/Agnoster/venv/lib/python3.12/site-packages/sqlalchemy/pool/base.py", line 449, in connect
    return _ConnectionFairy._checkout(self)
           ^^^^^^^^^^^^^^^^^^^^^^^^^^^^^^^^
  File "/Users/vrushank/Desktop/WORKSPACE/Agnoster/venv/lib/python3.12/site-packages/sqlalchemy/pool/base.py", line 1263, in _checkout
    fairy = _ConnectionRecord.checkout(pool)
            ^^^^^^^^^^^^^^^^^^^^^^^^^^^^^^^^
  File "/Users/vrushank/Desktop/WORKSPACE/Agnoster/venv/lib/python3.12/site-packages/sqlalchemy/pool/base.py", line 712, in checkout
    rec = pool._do_get()
          ^^^^^^^^^^^^^^
  File "/Users/vrushank/Desktop/WORKSPACE/Agnoster/venv/lib/python3.12/site-packages/sqlalchemy/pool/impl.py", line 168, in _do_get
    with util.safe_reraise():
  File "/Users/vrushank/Desktop/WORKSPACE/Agnoster/venv/lib/python3.12/site-packages/sqlalchemy/util/langhelpers.py", line 146, in __exit__
    raise exc_value.with_traceback(exc_tb)
  File "/Users/vrushank/Desktop/WORKSPACE/Agnoster/venv/lib/python3.12/site-packages/sqlalchemy/pool/impl.py", line 166, in _do_get
    return self._create_connection()
           ^^^^^^^^^^^^^^^^^^^^^^^^^
  File "/Users/vrushank/Desktop/WORKSPACE/Agnoster/venv/lib/python3.12/site-packages/sqlalchemy/pool/base.py", line 390, in _create_connection
    return _ConnectionRecord(self)
           ^^^^^^^^^^^^^^^^^^^^^^^
  File "/Users/vrushank/Desktop/WORKSPACE/Agnoster/venv/lib/python3.12/site-packages/sqlalchemy/pool/base.py", line 674, in __init__
    self.__connect()
  File "/Users/vrushank/Desktop/WORKSPACE/Agnoster/venv/lib/python3.12/site-packages/sqlalchemy/pool/base.py", line 900, in __connect
    with util.safe_reraise():
  File "/Users/vrushank/Desktop/WORKSPACE/Agnoster/venv/lib/python3.12/site-packages/sqlalchemy/util/langhelpers.py", line 146, in __exit__
    raise exc_value.with_traceback(exc_tb)
  File "/Users/vrushank/Desktop/WORKSPACE/Agnoster/venv/lib/python3.12/site-packages/sqlalchemy/pool/base.py", line 896, in __connect
    self.dbapi_connection = connection = pool._invoke_creator(self)
                                         ^^^^^^^^^^^^^^^^^^^^^^^^^^
  File "/Users/vrushank/Desktop/WORKSPACE/Agnoster/venv/lib/python3.12/site-packages/sqlalchemy/engine/create.py", line 643, in connect
    return dialect.connect(*cargs, **cparams)
           ^^^^^^^^^^^^^^^^^^^^^^^^^^^^^^^^^^
  File "/Users/vrushank/Desktop/WORKSPACE/Agnoster/venv/lib/python3.12/site-packages/sqlalchemy/engine/default.py", line 616, in connect
    return self.loaded_dbapi.connect(*cargs, **cparams)
           ^^^^^^^^^^^^^^^^^^^^^^^^^^^^^^^^^^^^^^^^^^^^
sqlalchemy.exc.OperationalError: (sqlite3.OperationalError) unable to open database file
(Background on this error at: https://sqlalche.me/e/20/e3q8)